Workbook

Sheet Read Me
A1: AU Small Finance Bank Ltd (NSE: AUBANK) - Educational Bank Valuation Model
A2: Independent Educational Equity Research. This is not an investment advice, not a recommendation, not a target price.
A4: Valuation Date: 29-May-2026 (NSE closing price)
A5: Information Cut-Off: 29-May-2026 (No document published after this date is used in the valuation model)
A6: Accounting Basis: STANDALONE (AU reports as a single bank; Fincare SFB was amalgamated w.e.f. 01-Apr-2024 by pooling of interests method).
A7: Units: INR crores unless stated; Per-share data in INR; Ratios as decimals formatted %. Fiscal Year ends 31 March (FY26 = 01-Apr-2025 to 31-Mar-2026).
A8: Forecast: FY27E-FY31E Explicit; FY32-FY41 Fade Stage; Continuing Value thereafter (3-Stage Residual Income).
A10: Colour / Format Convention
A11: Blue Font = Hard-Coded Input (reported data or analyst assumption; every one carries a source ID or a note).
A12: Black Font = Formula Green Font = Formula linking to another sheet Yellow Fill = Key Assumption / Scenario Lever
A13: Grey Fill "Active" Rows = Drivers actually used by the Model (chosen by the scenario selector on Inputs).
A15: Sheet Map
... A29: - FY25 is not comparable with earlier years (Fincare amalgamation); FY21 includes a one-off gain on sale of Aavas stake (per company presentation) and Covid provisioning.

Sheet Inputs
A1: Inputs, Scenario Selector and Driver Tables
A2: Blue = input; yellow = key lever; grey "Active" rows feed the Model. Units: decimals shown as %, INR crore unless stated.
A4: A. Dates, market data and cost of equity
A5: Valuation Date | C5: 46171 | I5: NSE close. Information Cut-Off = Same Date.
A6: Base Balance-Sheet Date (FY26 Year-End) | C6: 46112 | I6: Audited standalone balance sheet [S1]
A7: Days from FY-end to Valuation Date | C7: =C5-C6 -> 59 | I7: Used to roll value from 31-Mar-2026 to valuation date
A8: Closing Price, 29-May-2026 (INR) | C8: 984.7 | I8: [S15] NSE EQ series close. 52-wk range 682.15-1,079.55
A9: Equity Shares Outstanding, 31-Mar-2026 (crores) | C9: =Hist!H36/10 -> 74.82671 | I9: Paid-up capital / face value INR10 [S1]
A10: Dilution from ESOPs (basic EPS / diluted EPS - 1) | C10: =Hist!H72/Hist!H73-1 -> 0.011139674 | I10: FY26 basic 35.40 / diluted 35.01 [S1]; applied to period-end shares
A11: Diluted shares for valuation (crore) | C11: =C9*(1+C10) -> 75.660255 | I11: Calculated
A12: Risk-free rate (10-yr G-sec, INR) | C12: 0.072 | I12: [S18] Interpolated: 7-yr 7.07% (22-May) and 14-yr 7.34% (29-May) RBI auction cut-offs -> ~7.19%; rounded 7.20%
A13: Equity beta (2-yr weekly vs NIFTY 50) | C13: =Beta!F4 -> 1.0232624 | I13: [S15][S16] Regression beta, see Beta sheet
A14: Equity risk premium (India, INR) | C14: 0.06 | I14: Analyst assumption (judgement; common practitioner range 5-7%). Sensitised in Valuation tables.
A15: Cost of equity (CAPM) | C15: =C12+C13*C14 -> 0.13339575 | I15: Rf + beta x ERP
A17: B. Scenario selector
A18: Scenario selector (1 = Base, 2 = Upside, 3 = Downside) | C18: 1 | I18: Drives every "Active" row below
A20: C. Terminal / valuation assumptions (by scenario)
A21: Item | C21: Base | D21: Upside | E21: Downside | F21: Active
A22: Terminal (steady-state) ROE | C22: 0.15 | D22: 0.165 | E22: 0.13 | F22: =CHOOSE($C$18,C22,D22,E22) -> 0.15 | I22: Judgement: FY22-FY26 reported ROE 13-16% (S8 extract); peer private banks 11-13%; universal-bank transition adds competition. Terminal ROE applies after a 10-year linear fade.
A23: Terminal growth of book value / earnings | C23: 0.07 | D23: 0.075 | E23: 0.065 | F23: =CHOOSE($C$18,C23,D23,E23) -> 0.07 | I23: Below long-run nominal GDP; must be < CoE and consistent with ROE x retention (implied payout = 1 - g/ROE)
A24: Fade period (years, FY32-FY41) - structural | C24: =COUNT(Valuation!H16:Q16) -> 10 | I24: Number of fade columns on Valuation sheet.
A26: D. Regulatory and structural inputs
A27: Assumed universal-bank transition: first fiscal year (e.g. 2028 = FY28) | C27: 2028 | I27: Assumption. In-principle approval 7-Aug-2025 [S14]; final application filed Mar-2026 [S1].
A28: Operational-risk capital proxy: % of avg gross income (BIA-style) | C28: 0.15 | I28: Assumption for illustration; RWA = 12.5 x alpha x 3-yr avg (NII + other income)
A29: SFB minimum CET1 | C29: 0.06 | I29: [S6]
A30: SFB minimum Tier 1 | C30: 0.075 | I30: [S6]
A31: SFB minimum CRAR | C31: 0.15 | I31: [S6]
A32: Universal bank minimum CET1 incl. CCB | C32: 0.08 | I32: [S19] 5.5% + 2.5% CCB
A33: Universal bank minimum Tier 1 incl. CCB | C33: 0.095 | I33: [S19] 7% + 2.5% CCB
A34: Universal bank minimum CRAR incl. CCB | C34: 0.115 | I34: [S19] 9% + 2.5% CCB
A35: Internal CET1 floor used in capital check | C35: 0.12 | I35: Analyst assumption (management buffer)
A36: Minimum cash & bank balances / deposits (CRR proxy) | C36: 0.03 | I36: Assumption approximating CRR
A37: Maximum net advances / deposits (funding check) | C37: 0.92 | I37: Analyst limit for the funding-supportability check
A39: E. Driver tables FY27E-FY31E (Base / Upside / Downside / Active)
A40: Driver | B40: Case | C40: FY27E | D40: FY28E | E40: FY29E | F40: FY30E | G40: FY31E | H40: FY26A | I40: Rationale / evidence
A41: Loan growth - Retail Secured (Wheels, MBL, Housing, Gold) | B41: Base | C41: 0.2 | D41: 0.18 | E41: 0.17 | F41: 0.16 | G41: 0.15 | I41: FY26 +21.0% [S8]. Base fades toward ~15%; growth rate = lower end of management "2-2.5x nominal GDP" [S10]
B42: Upside | C42: 0.24 | D42: 0.22 | E42: 0.21 | F42: 0.2 | G42: 0.18
B43: Downside | C43: 0.1 | D43: 0.12 | E43: 0.15 | F43: 0.15 | G43: 0.14
B44: Active | C44: =CHOOSE($C$18,C41,C42,C43) -> 0.2 | D44: =CHOOSE($C$18,D41,D42,D43) -> 0.18 | E44: =CHOOSE($C$18,E41,E42,E43) -> 0.17 | F44: =CHOOSE($C$18,F41,F42,F43) -> 0.16 | G44: =CHOOSE($C$18,G41,G42,G43) -> 0.15 | H44: =Model!E13/Model!D13-1 -> 0.21047823
A46: Loan growth - Commercial Banking | B46: Base | C46: 0.25 | D46: 0.21 | E46: 0.2 | F46: 0.18 | G46: 0.16 | I46: FY26 +29.3% [S8]; base fade towards 15-16%
...

Sheet Model
A1: Integrated Forecast (INR crore unless stated) - Scenario Shown: | F1: =CHOOSE(Inputs!C18,"BASE","UPSIDE","DOWNSIDE") -> BASE
A2: Columns C-E = actuals linked to Hist; F-J = forecasts driven by Inputs "Active" rows. Cash & bank is the balancing item.
A4: Line item | B4: Unit | C4: FY24A | D4: FY25A | E4: FY26A | F4: FY27E | G4: FY28E | H4: FY29E | I4: FY30E | J4: FY31E | K4: Notes
A5: Fiscal year (numeric) | C5: 2024 | D5: 2025 | E5: 2026 | F5: 2027 | G5: 2028 | H5: 2029 | I5: 2030 | J5: 2031
A6: Loan book (gross loan portfolio by segment, reported for Mar-25 and Mar-26 [S8])
A7: Segment growth drivers are on Inputs; segment yields (Mar-26): RSA 14.2%, CB 10.4%, IB 25.2%, DU 14.2%, O&SME 8.0% [S8]
A13: GLP - Retail Secured Assets | B13: Rs cr | D13: 76616 | E13: 92742 | F13: =E13*(1+Inputs!C44) -> 111290.4 | G13: =F13*(1+Inputs!D44) -> 131322.67 | H13: =G13*(1+Inputs!E44) -> 153647.53 | I13: =H13*(1+Inputs!F44) -> 178231.13 | J13: =I13*(1+Inputs!G44) -> 204965.8 | K13: [S8] loan-mix slide
A14: GLP - Commercial Banking | B14: Rs cr | D14: 23952 | E14: 30968 | F14: =E14*(1+Inputs!C49) -> 38710 | G14: =F14*(1+Inputs!D49) -> 46839.1 | H14: =G14*(1+Inputs!E49) -> 56206.92 | I14: =H14*(1+Inputs!F49) -> 66324.166 | J14: =I14*(1+Inputs!G49) -> 76936.032 | K14: [S8] loan-mix slide
A15: GLP - Inclusive Banking (MFI) | B15: Rs cr | D15: 6937 | E15: 7150 | F15: =E15*(1+Inputs!C54) -> 7507.5 | G15: =F15*(1+Inputs!D54) -> 8108.1 | H15: =G15*(1+Inputs!E54) -> 9081.072 | I15: =H15*(1+Inputs!F54) -> 10170.801 | J15: =I15*(1+Inputs!G54) -> 11391.297 | K15: [S8] loan-mix slide
A16: GLP - Digital Unsecured | B16: Rs cr | D16: 3290 | E16: 2949 | F16: =E16*(1+Inputs!C59) -> 2949 | G16: =F16*(1+Inputs!D59) -> 3243.9 | H16: =G16*(1+Inputs!E59) -> 3730.485 | I16: =H16*(1+Inputs!F59) -> 4290.0577 | J16: =I16*(1+Inputs!G59) -> 4933.5664 | K16: [S8] loan-mix slide
A17: GLP - Others & SME | B17: Rs cr | D17: 4909 | E17: 6518 | F17: =E17*(1+Inputs!C64) -> 7821.6 | G17: =F17*(1+Inputs!D64) -> 9229.488 | H17: =G17*(1+Inputs!E64) -> 10706.206 | I17: =H17*(1+Inputs!F64) -> 12312.137 | J17: =I17*(1+Inputs!G64) -> 14158.958 | K17: [S8] loan-mix slide
A18: Gross loan portfolio (GLP) | B18: Rs cr | C18: =Hist!F47 -> 73999 | D18: =SUM(D13:D17) -> 115704 | E18: =SUM(E13:E17) -> 140327 | F18: =SUM(F13:F17) -> 168278.5 | G18: =SUM(G13:G17) -> 198743.26 | H18: =SUM(H13:H17) -> 233372.21 | I18: =SUM(I13:I17) -> 271328.29 | J18: =SUM(J13:J17) -> 312385.65 | K18: Mar-24 per [S11]; ties to reported 140,327 / 115,704
A19: GLP growth | B19: % | D19: =D18/C18-1 -> 0.5635887 | E19: =E18/D18-1 -> 0.21281027 | F19: =F18/E18-1 -> 0.19918832 | G19: =G18/F18-1 -> 0.18103774 | H19: =H18/G18-1 -> 0.17423962 | I19: =I18/H18-1 -> 0.16264183 | J19: =J18/I18-1 -> 0.15131987 | K19: FY25 includes Fincare book
A20: Net advances / GLP | B20: x | C20: =C21/C18 -> 0.98869788 | D20: =D21/D18 -> 0.92557288 | E20: =E21/E18 -> 0.95687666 | F20: =Inputs!C69 -> 0.957 | G20: =Inputs!D69 -> 0.957 | H20: =Inputs!E69 -> 0.957 | I20: =Inputs!F69 -> 0.957 | J20: =Inputs!G69 -> 0.957
A21: Net advances (balance sheet) | B21: Rs cr | C21: =Hist!F32 -> 73162.655 | D21: =Hist!G32 -> 107092.48 | E21: =Hist!H32 -> 134275.63 | F21: =F18*F20 -> 161042.52 | G21: =G18*G20 -> 190197.3 | H21: =H18*H20 -> 223337.2 | I21: =I18*I20 -> 259661.17 | J21: =J18*J20 -> 298953.07
A22: Net advances growth | B22: % | D22: =D21/C21-1 -> 0.46375887 | E22: =E21/D21-1 -> 0.2538287 | F22: =F21/E21-1 -> 0.1993429 | G22: =G21/F21-1 -> 0.18103774 | H22: =H21/G21-1 -> 0.17423962 | I22: =I21/H21-1 -> 0.16264183 | J22: =J21/I21-1 -> 0.15131987
A24: Funding
A25: Deposits | B25: Rs cr | C25: =Hist!F40 -> 87182.116 | D25: =Hist!G40 -> 124268.54 | E25: =Hist!H40 -> 152661.16 | F25: =F21/F26 -> 183002.87 | G25: =G21/G26 -> 216133.3 | H25: =H21/H26 -> 253792.28 | I25: =I21/I26 -> 295069.52 | J25: =J21/J26 -> 339719.4 | K25: Deposits = net advances / CD ratio
A26: Net advances / deposits | B26: % | C26: =C21/C25 -> 0.83919338 | D26: =D21/D25 -> 0.86178273 | E26: =E21/E25 -> 0.87956641 | F26: =Inputs!C74 -> 0.88 | G26: =Inputs!D74 -> 0.88 | H26: =Inputs!E74 -> 0.88 | I26: =Inputs!F74 -> 0.88 | J26: =Inputs!G74 -> 0.88
A27: CASA deposits | B27: Rs cr | C27: =Hist!F48 -> 29126 | E27: =Hist!H48 -> 43357 | F27: =F25*F28 -> 52155.818 | G27: =G25*G28 -> 62678.656 | H27: =H25*H28 -> 74868.722 | I27: =I25*I28 -> 88520.855 | J27: =J25*J28 -> 103614.42
A28: CASA ratio | B28: % | C28: =C27/C25 -> 0.33408228 | E28: =E27/E25 -> 0.28400805 | F28: =Inputs!C79 -> 0.285 | G28: =Inputs!D79 -> 0.29 | H28: =Inputs!E79 -> 0.295 | I28: =Inputs!F79 -> 0.3 | J28: =Inputs!G79 -> 0.305
A29: Term deposits (incl. CDs) | B29: Rs cr | C29: =C25-C27 -> 58056.116 | E29: =E25-E27 -> 109304.16 | F29: =F25-F27 -> 130847.05 | G29: =G25-G27 -> 153454.64 | H29: =H25-H27 -> 178923.56 | I29: =I25-I27 -> 206548.66 | J29: =J25-J27 -> 236104.98
A30: Deposit growth | B30: % | D30: =D25/C25-1 -> 0.42539031 | E30: =E25/D25-1 -> 0.22847793 | F30: =F25/E25-1 -> 0.19875196 | G30: =G25/F25-1 -> 0.18103774 | H30: =H25/G25-1 -> 0.17423962 | I30: =I25/H25-1 -> 0.16264183 | J30: =J25/I25-1 -> 0.15131987
A31: Borrowings | B31: Rs cr | C31: =Hist!F41 -> 5479.3721 | D31: =Hist!G41 -> 11659.902 | E31: =Hist!H41 -> 13871.545 | F31: =F25*Inputs!C89 -> 16470.258 | G31: =G25*Inputs!D89 -> 19451.997 | H31: =H25*Inputs!E89 -> 22841.305 | I31: =I25*Inputs!F89 -> 26556.257 | J31: =J25*Inputs!G89 -> 30574.746 | K31: Ratio to deposits (Inputs)
A32: Other liabilities & provisions | B32: Rs cr | C32: =Hist!F42 -> 4204.6499 | D32: =Hist!G42 -> 4750.9383 | E32: =Hist!H42 -> 5291.2379 | F32: =F25*Inputs!C94 -> 6405.1004 | G32: =G25*Inputs!D94 -> 7564.6653 | H32: =H25*Inputs!E94 -> 8882.7297 | I32: =I25*Inputs!F94 -> 10327.433 | J32: =J25*Inputs!G94 -> 11890.179
A33: Shareholders' funds (from equity roll-forward) | B33: Rs cr | C33: =Hist!F39 -> 12559.532 | D33: =Hist!G39 -> 17166.282 | E33: =Hist!H39 -> 19973.522 | F33: =F80 -> 23622.054 | G33: =G80 -> 28130.061 | H33: =H80 -> 33552.506 | I33: =I80 -> 40011.329 | J33: =J80 -> 47661.969
A34: Total liabilities & equity | B34: Rs cr | C34: =C25+C31+C32+C33 -> 109425.67 | D34: =D25+D31+D32+D33 -> 157845.67 | E34: =E25+E31+E32+E33 -> 191797.47 | F34: =F25+F31+F32+F33 -> 229500.28 | G34: =G25+G31+G32+G33 -> 271280.02 | H34: =H25+H31+H32+H33 -> 319068.82 | I34: =I25+I31+I32+I33 -> 371964.54 | J34: =J25+J31+J32+J33 -> 429846.29
A36: Assets
A37: Cash & balances with RBI | B37: Rs cr | C37: =Hist!F29 -> 4638.0094 | D37: =Hist!G29 -> 8604.6221 | E37: =Hist!H29 -> 6973.2602 | K37: Actuals only; forecast shown combined in row 39
A38: Balances with banks & money at call | B38: Rs cr | C38: =Hist!F30 -> 1738.3249 | D38: =Hist!G30 -> 861.7397 | E38: =Hist!H30 -> 1550.1495
A39: Cash & bank balances (BALANCING ITEM) | B39: Rs cr | C39: =C37+C38 -> 6376.3343 | D39: =D37+D38 -> 9466.3618 | E39: =E37+E38 -> 8523.4097 | F39: =F34-F21-F40-F41-F42 -> 10425.012 | G39: =G34-G21-G40-G41-G42 -> 12671.897 | H39: =H34-H21-H40-H41-H42 -> 15529.947 | I39: =I34-I21-I40-I41-I42 -> 19177.31 | J39: =J34-J21-J40-J41-J42 -> 23783.274 | K39: Plug = total L&E - other assets; tested against minimum liquidity
A40: Investments | B40: Rs cr | C40: =Hist!F31 -> 27133.365 | D40: =Hist!G31 -> 37847.524 | E40: =Hist!H31 -> 44793.651 | F40: =F25*Inputs!C84 -> 53070.832 | G40: =G25*Inputs!D84 -> 62678.656 | H40: =H25*Inputs!E84 -> 73599.761 | I40: =I25*Inputs!F84 -> 85570.16 | J40: =J25*Inputs!G84 -> 98518.625
A41: Fixed assets | B41: Rs cr | C41: =Hist!F33 -> 851.5924 | D41: =Hist!G33 -> 912.4652 | E41: =Hist!H33 -> 1436.382 | F41: =E41*(1+Inputs!C104) -> 1580.0202 | G41: =F41*(1+Inputs!D104) -> 1738.0222 | H41: =G41*(1+Inputs!E104) -> 1911.8244 | I41: =H41*(1+Inputs!F104) -> 2103.0069 | J41: =I41*(1+Inputs!G104) -> 2313.3076
A42: Other assets | B42: Rs cr | C42: =Hist!F34 -> 1901.7232 | D42: =Hist!G34 -> 2526.8312 | E42: =Hist!H34 -> 2768.3941 | F42: =F21*Inputs!C99 -> 3381.893 | G42: =G21*Inputs!D99 -> 3994.1433 | H42: =H21*Inputs!E99 -> 4690.0813 | I42: =I21*Inputs!F99 -> 5452.8847 | J42: =J21*Inputs!G99 -> 6278.0145
A43: Total assets | B43: Rs cr | C43: =C21+C39+C40+C41+C42 -> 109425.67 | D43: =D21+D39+D40+D41+D42 -> 157845.67 | E43: =E21+E39+E40+E41+E42 -> 191797.47 | F43: =F21+F39+F40+F41+F42 -> 229500.28 | G43: =G21+G39+G40+G41+G42 -> 271280.02 | H43: =H21+H39+H40+H41+H42 -> 319068.82 | I43: =I21+I39+I40+I41+I42 -> 371964.54 | J43: =J21+J39+J40+J41+J42 -> 429846.29
A44: Balance check: assets - (liabilities + equity) | B44: Rs cr | C44: =ROUND(C43-C34,2) -> 0 | D44: =ROUND(D43-D34,2) -> 0 | E44: =ROUND(E43-E34,2) -> 0 | F44: =ROUND(F43-F34,2) -> 0 | G44: =ROUND(G43-G34,2) -> 0 | H44: =ROUND(H43-H34,2) -> 0 | I44: =ROUND(I43-I34,2) -> 0 | J44: =ROUND(J43-J34,2) -> 0 | K44: Must be 0
A45: Non-cash assets (adv + inv + fixed + other) | B45: Rs cr | C45: =C21+C40+C41+C42 -> 103049.34 | D45: =D21+D40+D41+D42 -> 148379.3 | E45: =E21+E40+E41+E42 -> 183274.06 | F45: =F21+F40+F41+F42 -> 219075.27 | G45: =G21+G40+G41+G42 -> 258608.12 | H45: =H21+H40+H41+H42 -> 303538.87 | I45: =I21+I40+I41+I42 -> 352787.23 | J45: =J21+J40+J41+J42 -> 406063.02 | K45: Driver base for other income and opex (avoids circularity)
A46: Interest-earning assets (adv + inv + cash & bank) | B46: Rs cr | C46: =C21+C39+C40 -> 106672.35 | D46: =D21+D39+D40 -> 154406.37 | E46: =E21+E39+E40 -> 187592.69 | F46: =F21+F39+F40 -> 224538.37 | G46: =G21+G39+G40 -> 265547.85 | H46: =H21+H39+H40 -> 312466.91 | I46: =I21+I39+I40 -> 364408.64 | J46: =J21+J39+J40 -> 421254.97
A47: Cash & bank / deposits (vs minimum on Inputs) | B47: % | C47: =C39/C25 -> 0.073138099 | D47: =D39/D25 -> 0.076176653 | E47: =E39/E25 -> 0.055832207 | F47: =F39/F25 -> 0.056966386 | G47: =G39/G25 -> 0.058630008 | H47: =H39/H25 -> 0.061191568 | I47: =I39/I25 -> 0.064992514 | J47: =J39/J25 -> 0.070008584
A49: Income statement
...

Sheet Valuation
A1: Valuation - Residual Income (Primary) and Justified P/B-ROE (cross-check)
A2: =CONCATENATE("Scenario: ",Model!F1," | CoE ",TEXT(Inputs!C15,"0.00%")," | terminal ROE ",TEXT(Inputs!F22,"0.0%")," | terminal g ",TEXT(Inputs!F23,"0.0%")) -> Scenario: BASE | CoE 13.34% | terminal ROE 15.0% | terminal g 7.0%
A4: Key inputs
A5: Cost of equity | B5: =Inputs!C15 -> 0.13339575
A6: Terminal growth | B6: =Inputs!F23 -> 0.07
A7: Terminal ROE | B7: =Inputs!F22 -> 0.15
A8: Book value 31-Mar-2026 (Rs cr) | B8: =Model!E80 -> 19973.522
A9: Days 31-Mar-26 to valuation date | B9: =Inputs!C7 -> 59
A10: Diluted shares (cr) | B10: =Inputs!C11 -> 75.660255
A11: Share price (INR) | B11: =Inputs!C8 -> 984.7
A13: Stage 1 (explicit, Model) and Stage 2 (fade)
A14: Year | B14: FY26A | C14: FY27E | D14: FY28E | E14: FY29E | F14: FY30E | G14: FY31E | H14: FY32 | I14: FY33 | J14: FY34 | K14: FY35 | L14: FY36 | M14: FY37 | N14: FY38 | O14: FY39 | P14: FY40 | Q14: FY41
A15: Period index t (years from 31-Mar-2026) | C15: =B15+1 -> 1 | D15: =C15+1 -> 2 | E15: =D15+1 -> 3 | F15: =E15+1 -> 4 | G15: =F15+1 -> 5 | H15: =G15+1 -> 6 | I15: =H15+1 -> 7 | J15: =I15+1 -> 8 | ... Q15: =P15+1 -> 15
A16: Fade step i (0 in explicit stage) | C16: 0 | D16: 0 | E16: 0 | F16: 0 | G16: 0 | H16: =IF(H15>5,H15-5,0) -> 1 | I16: =IF(I15>5,I15-5,0) -> 2 | J16: =IF(J15>5,J15-5,0) -> 3 | K16: =IF(K15>5,K15-5,0) -> 4 | L16: =IF(L15>5,L15-5,0) -> 5 | M16: =IF(M15>5,M15-5,0) -> 6 | N16: =IF(N15>5,N15-5,0) -> 7 | O16: =IF(O15>5,O15-5,0) -> 8 | ... Q16: =IF(Q15>5,Q15-5,0) -> 10
A17: Opening book value | C17: =Model!F74 -> 19973.522 | D17: =Model!G74 -> 23622.054 | E17: =Model!H74 -> 28130.061 | F17: =Model!I74 -> 33552.506 | G17: =Model!J74 -> 40011.329 | H17: =G20 -> 47661.969 | I17: =H20 -> 56197.781 | J17: =I20 -> 65581.095 | K17: =J20 -> 75736.214 | L17: =K20 -> 86545.824 | M17: =L20 -> 97849.22 | N17: =M20 -> 109442.86 | O17: =N20 -> 121083.59 | ... Q17: =P20 -> 143375.42
A18: ROE on opening book value | C18: =C19/C17 -> 0.17389818 | D18: =D19/D17 -> 0.18344013 | E18: =E19/E17 -> 0.18656454 | F18: =F19/F17 -> 0.18844684 | G18: =G19/G17 -> 0.18782878 | H18: =$G$18+($B$7-$G$18)*H16/Inputs!$C$24 -> 0.18404591 | I18: =$G$18+($B$7-$G$18)*I16/Inputs!$C$24 -> 0.18026303 | J18: =$G$18+($B$7-$G$18)*J16/Inputs!$C$24 -> 0.17648015 | K18: =$G$18+($B$7-$G$18)*K16/Inputs!$C$24 -> 0.17269727 | L18: =$G$18+($B$7-$G$18)*L16/Inputs!$C$24 -> 0.16891439 | M18: =$G$18+($B$7-$G$18)*M16/Inputs!$C$24 -> 0.16513151 | N18: =$G$18+($B$7-$G$18)*N16/Inputs!$C$24 -> 0.16134864 | O18: =$G$18+($B$7-$G$18)*O16/Inputs!$C$24 -> 0.15756576 | ... Q18: =$G$18+($B$7-$G$18)*Q16/Inputs!$C$24 -> 0.15
A19: Net income | C19: =Model!F70 -> 3473.3592 | D19: =Model!G70 -> 4333.2328 | E19: =Model!H70 -> 5248.0719 | F19: =Model!I70 -> 6322.8638 | G19: =Model!J70 -> 7515.2794 | H19: =H18*H17 -> 8771.9902 | I19: =I18*I17 -> 10130.382 | J19: =J18*J17 -> 11573.761 | K19: =K18*K17 -> 13079.437 | L19: =L18*L17 -> 14618.835 | M19: =M18*M17 -> 16157.99 | N19: =N18*N17 -> 17658.456 | O19: =O18*O17 -> 19078.627 | ... Q19: =Q18*Q17 -> 21506.313
A20: Closing book value | B20: =Model!E80 -> 19973.522 | C20: =Model!F80 -> 23622.054 | D20: =Model!G80 -> 28130.061 | E20: =Model!H80 -> 33552.506 | F20: =Model!I80 -> 40011.329 | G20: =Model!J80 -> 47661.969 | H20: =H17*(1+H21) -> 56197.781 | I20: =I17*(1+I21) -> 65581.095 | J20: =J17*(1+J21) -> 75736.214 | K20: =K17*(1+K21) -> 86545.824 | L20: =L17*(1+L21) -> 97849.22 | M20: =M17*(1+M21) -> 109442.86 | N20: =N17*(1+N21) -> 121083.59 | O20: =O17*(1+O21) -> 132494.79 | ... Q20: =Q17*(1+Q21) -> 153411.7
A21: Book value growth | C21: =C20/C17-1 -> 0.18266846 | D21: =D20/D17-1 -> 0.19083887 | E21: =E20/E17-1 -> 0.19276337 | F21: =F20/F17-1 -> 0.192499 | G21: =G20/G17-1 -> 0.19121182 | H21: =$G$21+($B$6-$G$21)*H16/Inputs!$C$24 -> 0.17909064 | I21: =$G$21+($B$6-$G$21)*I16/Inputs!$C$24 -> 0.16696946 | J21: =$G$21+($B$6-$G$21)*J16/Inputs!$C$24 -> 0.15484828 | K21: =$G$21+($B$6-$G$21)*K16/Inputs!$C$24 -> 0.14272709 | L21: =$G$21+($B$6-$G$21)*L16/Inputs!$C$24 -> 0.13060591 | M21: =$G$21+($B$6-$G$21)*M16/Inputs!$C$24 -> 0.11848473 | N21: =$G$21+($B$6-$G$21)*N16/Inputs!$C$24 -> 0.10636355 | O21: =$G$21+($B$6-$G$21)*O16/Inputs!$C$24 -> 0.094242365 | ... Q21: =$G$21+($B$6-$G$21)*Q16/Inputs!$C$24 -> 0.07
A22: Residual income = NI - k x opening BV | C22: =C19-$B$5*C17 -> 808.97631 | D22: =D19-$B$5*D17 -> 1182.1512 | E22: =E19-$B$5*E17 -> 1495.6415 | F22: =F19-$B$5*F17 -> 1847.1023 | G22: =G19-$B$5*G17 -> 2177.9383 | H22: =H19-$B$5*H17 -> 2414.0864 | I22: =I19-$B$5*I17 -> 2633.8373 | J22: =J19-$B$5*J17 -> 2825.5224 | ... Q22: =Q19-$B$5*Q17 -> 2380.642
A23: Discount factor 1/(1+k)^t | C23: =1/(1+$B$5)^C15 -> 0.88230435 | D23: =1/(1+$B$5)^D15 -> 0.77846097 | E23: =1/(1+$B$5)^E15 -> 0.6868395 | F23: =1/(1+$B$5)^F15 -> 0.60600148 | G23: =1/(1+$B$5)^G15 -> 0.53467775 | H23: =1/(1+$B$5)^H15 -> 0.4717485 | I23: =1/(1+$B$5)^I15 -> 0.41622576 | J23: =1/(1+$B$5)^J15 -> 0.3672378 | ... Q23: =1/(1+$B$5)^Q15 -> 0.15285383
A24: PV of residual income | C24: =C22*C23 -> 713.76332 | D24: =D22*D23 -> 920.2586 | E24: =E22*E23 -> 1027.2656 | F24: =F22*F23 -> 1119.3467 | G24: =G22*G23 -> 1164.4951 | H24: =H22*H23 -> 1138.8416 | I24: =I22*I23 -> 1096.2709 | J24: =J22*J23 -> 1037.6386 | ... Q24: =Q22*Q23 -> 363.89025
A25: Implied payout in fade (1 - BV growth / ROE) | H25: =1-H21/H18 -> 0.026924064 | I25: =1-I21/I18 -> 0.073745393 | J25: =1-J21/J18 -> 0.12257397 | K25: =1-K21/K18 -> 0.17354169 | L25: =1-L21/L18 -> 0.22679228 | M25: =1-M21/M18 -> 0.28248263 | N25: =1-N21/N18 -> 0.34078434 | O25: =1-O21/O18 -> 0.40188549 | ... Q25: =1-Q21/Q18 -> 0.53333333
A26: Note: in the explicit stage, BV also changes with ESOP additions (non-income); RI uses Model PAT and opening BV. Fade stage assumes clean surplus.
A28: Residual income value
A29: Book value at 31-Mar-2026 | B29: =$B$8 -> 19973.522
A30: PV of RI - explicit FY27-FY31 | B30: =SUM(C24:G24) -> 4945.1294
A31: PV of RI - fade FY32-FY41 | B31: =SUM(H24:Q24) -> 7986.585
A32: Continuing value at FY41: (ROE_T - k) x BV_FY41 / (k - g) | B32: =($B$7-$B$5)*Q20/($B$5-$B$6) -> 40180.724
A33: PV of continuing value | B33: =B32*Q23 -> 6141.7777
A34: Equity value at 31-Mar-2026 | B34: =B29+B30+B31+B33 -> 39047.014
A35: Equity value at valuation date (rolled forward at k) | B35: =B34*(1+$B$5)^($B$9/365) -> 39845.408
A36: Value per diluted share (INR) | B36: =B35/$B$10 -> 526.63592
A37: Implied difference vs market price | B37: =B36/$B$11-1 -> -0.46518136
A38: Implied P/B on Mar-26 BV | B38: =B35/$B$8 -> 1.9949115
A39: Implied P/E on FY27E EPS | B39: =B36/Model!F85 -> 11.502383
A40: Share of value from continuing value | B40: =B33/B34 -> 0.15729186
A42: Justified P/B - ROE framework: P/B = (ROE - g) / (k - g)
A43: Sustainable ROE basis | B43: ROE | C43: P/B | D43: Value/share | E43: vs price
A44: FY26A reported ROE (14.2%) | B44: =Hist!H52 -> 0.142 | C44: =(B44-$B$6)/($B$5-$B$6) -> 1.1357229 | D44: =C44*$B$8/$B$10*(1+$B$5)^($B$9/365) -> 305.94945 | E44: =D44/$B$11-1 -> -0.68929679
...

Sheet Hist
A1: Historical standalone financials, FY21-FY26 (INR crore unless stated)
A2: Reported figures in blue (converted from INR lakh /100). Calculated rows in black. FY25 not comparable (Fincare amalgamation, pooling). FY21 = regrouped comparative per FY22 filing.
A4: Line item | B4: Unit | C4: FY21 | D4: FY22 | E4: FY23 | F4: FY24 | G4: FY25 | H4: FY26 | I4: Source / note
A5: Income statement
A6: Interest/discount on advances | B6: Rs cr | C6: 3947.3625 | D6: 4881.5523 | E6: 6847.0183 | F6: 8442.1476 | G6: 13368.347 | H6: 15711.109 | I6: [S4] FY21-22, [S3] FY23-24, [S1] FY25-26; verified [S2][S5]
A7: Income on investments | B7: Rs cr | C7: 773.043 | D7: 780.532 | E7: 1189.8843 | F7: 1632.3875 | G7: 2238.176 | H7: 2647.2074 | I7: [S4] FY21-22, [S3] FY23-24, [S1] FY25-26; verified [S2][S5]
A8: Interest on RBI balances & inter-bank funds | B8: Rs cr | C8: 85.0066 | D8: 87.0812 | E8: 58.2772 | F8: 66.8798 | G8: 69.1482 | H8: 92.5533 | I8: [S4] FY21-22, [S3] FY23-24, [S1] FY25-26; verified [S2][S5]
A9: Other interest | B9: Rs cr | C9: 144.6394 | D9: 172.5652 | E9: 110.2285 | F9: 413.2982 | G9: 388.0596 | H9: 185.469 | I9: [S4] FY21-22, [S3] FY23-24, [S1] FY25-26; verified [S2][S5]
A10: Interest earned | B10: Rs cr | C10: =SUM(C6:C9) -> 4950.0515 | D10: =SUM(D6:D9) -> 5921.7307 | E10: =SUM(E6:E9) -> 8205.4083 | F10: =SUM(F6:F9) -> 10554.713 | G10: =SUM(G6:G9) -> 16063.731 | H10: =SUM(H6:H9) -> 18636.339 | I10: Calc; ties to reported (Checks)
A11: Interest expended | B11: Rs cr | C11: 2584.6097 | D11: 2687.6058 | E11: 3780.1264 | F11: 5397.6293 | G11: 8052.1494 | H11: 9523.6562 | I11: [S4] FY21-22, [S3] FY23-24, [S1] FY25-26; verified [S2][S5]; FY24 per XBRL
A12: Net interest income (NII) | B12: Rs cr | C12: =C10-C11 -> 2365.4418 | D12: =D10-D11 -> 3234.1249 | E12: =E10-E11 -> 4425.2819 | F12: =F10-F11 -> 5157.0838 | G12: =G10-G11 -> 8011.5815 | H12: =H10-H11 -> 9112.6828 | I12: Calc
A13: Other income | B13: Rs cr | C13: 1420.9327 | D13: 993.6942 | E13: 1034.4642 | F13: 1745.8928 | G13: 2526.3111 | H13: 2977.9386 | I13: [S4] FY21-22, [S3] FY23-24, [S1] FY25-26; verified [S2][S5]. FY21 includes Aavas stake-sale gain (co. presentation) - one-off
A14: Net total income | B14: Rs cr | C14: =C12+C13 -> 3786.3745 | D14: =D12+D13 -> 4227.8191 | E14: =E12+E13 -> 5459.7461 | F14: =F12+F13 -> 6902.9766 | G14: =G12+G13 -> 10537.893 | H14: =H12+H13 -> 12090.621 | I14: Calc
A15: Employee cost | B15: Rs cr | C15: 980.1731 | D15: 1378.9217 | E15: 1793.0283 | F15: 2103.6806 | G15: 3147.7604 | H15: 3848.1619 | I15: [S4] FY21-22, [S3] FY23-24, [S1] FY25-26; verified [S2][S5]
A16: Other operating expenses | B16: Rs cr | C16: 678.2521 | D16: 1033.8526 | E16: 1647.2416 | F16: 2284.3216 | G16: 2809.4549 | H16: 3153.6996 | I16: [S4] FY21-22, [S3] FY23-24, [S1] FY25-26; verified [S2][S5]
A17: Operating expenses | B17: Rs cr | C17: =C15+C16 -> 1658.4252 | D17: =D15+D16 -> 2412.7743 | E17: =E15+E16 -> 3440.2699 | F17: =F15+F16 -> 4388.0022 | G17: =G15+G16 -> 5957.2153 | H17: =H15+H16 -> 7001.8615 | I17: Calc
A18: Pre-provision operating profit (PPOP) | B18: Rs cr | C18: =C14-C17 -> 2127.9493 | D18: =D14-D17 -> 1815.0448 | E18: =E14-E17 -> 2019.4762 | F18: =F14-F17 -> 2514.9744 | G18: =G14-G17 -> 4580.6773 | H18: =H14-H17 -> 5088.7599 | I18: Calc
A19: Provisions & contingencies (ex tax) | B19: Rs cr | C19: 669.4411 | D19: 360.9743 | E19: 154.8394 | F19: 438.7439 | G19: 1792.6232 | H19: 1614.7143 | I19: [S4] FY21-22, [S3] FY23-24, [S1] FY25-26; verified [S2][S5]
A20: Exceptional items (expense) | B20: Rs cr | C20: 0 | D20: 0 | E20: 0 | F20: 76.8014 | G20: 0 | H20: 0 | I20: FY24: Fincare merger expenses Rs76.8 cr [S3][S5]
A21: Profit before tax | B21: Rs cr | C21: =C18-C19-C20 -> 1458.5082 | D21: =D18-D19-D20 -> 1454.0705 | E21: =E18-E19-E20 -> 1864.6368 | F21: =F18-F19-F20 -> 1999.4291 | G21: =G18-G19-G20 -> 2788.0541 | H21: =H18-H19-H20 -> 3474.0456 | I21: Calc
A22: Tax expense | B22: Rs cr | C22: 287.8236 | D22: 324.2362 | E22: 436.7115 | F22: 464.7101 | G22: 682.1275 | H22: 832.7913 | I22: [S4] FY21-22, [S3] FY23-24, [S1] FY25-26; verified [S2][S5]
A23: Net profit (PAT) | B23: Rs cr | C23: =C21-C22 -> 1170.6846 | D23: =D21-D22 -> 1129.8343 | E23: =E21-E22 -> 1427.9253 | F23: =F21-F22 -> 1534.719 | G23: =G21-G22 -> 2105.9266 | H23: =H21-H22 -> 2641.2543 | I23: Calc; ties to reported PAT (Checks)
A24: Net profit as reported | B24: Rs cr | C24: 1170.6846 | D24: 1129.8342 | E24: 1427.9253 | F24: 1534.719 | G24: 2105.9266 | H24: 2641.2543 | I24: [S4] FY21-22, [S3] FY23-24, [S1] FY25-26; verified [S2][S5]
A25: Interest earned as reported | B25: Rs cr | C25: 4950.0515 | D25: 5921.7307 | E25: 8205.4083 | F25: 10554.713 | G25: 16063.731 | H25: 18636.339 | I25: [S4] FY21-22, [S3] FY23-24, [S1] FY25-26; verified [S2][S5]
A26: PBT as reported | B26: Rs cr | C26: 1458.5082 | D26: 1454.0705 | E26: 1864.6368 | F26: 1999.4291 | G26: 2788.0541 | H26: 3474.0456 | I26: [S4] FY21-22, [S3] FY23-24, [S1] FY25-26; verified [S2][S5]
A28: Balance sheet (31 March)
A29: Cash & balances with RBI | B29: Rs cr | C29: 1569.3478 | D29: 2468.4072 | E29: 8916.093 | F29: 4638.0094 | G29: 8604.6221 | H29: 6973.2602 | I29: [S4] FY21-22, [S3] FY23-24, [S1] FY25-26
A30: Balances with banks & money at call | B30: Rs cr | C30: 3211.9877 | D30: 3460.1078 | E30: 509.0793 | F30: 1738.3249 | G30: 861.7397 | H30: 1550.1495 | I30: [S4] FY21-22, [S3] FY23-24, [S1] FY25-26
A31: Investments | B31: Rs cr | C31: 10815.414 | D31: 15306.504 | E31: 20072.01 | F31: 27133.365 | G31: 37847.524 | H31: 44793.651 | I31: [S4] FY21-22, [S3] FY23-24, [S1] FY25-26
A32: Advances (net) | B32: Rs cr | C32: 34608.914 | D32: 46095.256 | E32: 58421.544 | F32: 73162.655 | G32: 107092.48 | H32: 134275.63 | I32: [S4] FY21-22, [S3] FY23-24, [S1] FY25-26
A33: Fixed assets | B33: Rs cr | C33: 482.3685 | D33: 622.5713 | E33: 740.1394 | F33: 851.5924 | G33: 912.4652 | H33: 1436.382 | I33: [S4] FY21-22, [S3] FY23-24, [S1] FY25-26
A34: Other assets | B34: Rs cr | C34: 903.2738 | D34: 1124.9534 | E34: 1557.2527 | F34: 1901.7232 | G34: 2526.8312 | H34: 2768.3941 | I34: [S4] FY21-22, [S3] FY23-24, [S1] FY25-26
A35: Total assets | B35: Rs cr | C35: =SUM(C29:C34) -> 51591.306 | D35: =SUM(D29:D34) -> 69077.8 | E35: =SUM(E29:E34) -> 90216.118 | F35: =SUM(F29:F34) -> 109425.67 | G35: =SUM(G29:G34) -> 157845.67 | H35: =SUM(H29:H34) -> 191797.47 | I35: Calc
A36: Share capital (face value INR10) | B36: Rs cr | C36: 312.2134 | D36: 314.9 | E36: 666.745 | F36: 669.1625 | G36: 744.5305 | H36: 748.2671 | I36: [S4] FY21-22, [S3] FY23-24, [S1] FY25-26
A37: Employee stock options outstanding | B37: Rs cr | C37: 103.1171 | D37: 41.3316 | E37: 44.0252 | F37: 62.7256 | G37: 124.235 | H37: 240.7582 | I37: [S4] FY21-22, [S3] FY23-24, [S1] FY25-26
A38: Reserves & surplus | B38: Rs cr | C38: 5859.8853 | D38: 7157.7824 | E38: 10266.574 | F38: 11827.643 | G38: 16297.516 | H38: 18984.497 | I38: [S4] FY21-22, [S3] FY23-24, [S1] FY25-26
A39: Shareholders' funds (net worth incl. ESOP o/s) | B39: Rs cr | C39: =SUM(C36:C38) -> 6275.2158 | D39: =SUM(D36:D38) -> 7514.014 | E39: =SUM(E36:E38) -> 10977.344 | F39: =SUM(F36:F38) -> 12559.532 | G39: =SUM(G36:G38) -> 17166.282 | H39: =SUM(H36:H38) -> 19973.522 | I39: Calc; FY26 = Rs19,974 cr = co. shareholders funds [S9]
A40: Deposits | B40: Rs cr | C40: 35979.314 | D40: 52584.621 | E40: 69364.986 | F40: 87182.116 | G40: 124268.54 | H40: 152661.16 | I40: [S4] FY21-22, [S3] FY23-24, [S1] FY25-26
A41: Borrowings | B41: Rs cr | C41: 7029.6957 | D41: 5990.7786 | E41: 6298.6521 | F41: 5479.3721 | G41: 11659.902 | H41: 13871.545 | I41: [S4] FY21-22, [S3] FY23-24, [S1] FY25-26
A42: Other liabilities & provisions | B42: Rs cr | C42: 2307.0802 | D42: 2988.3872 | E42: 3575.1362 | F42: 4204.6499 | G42: 4750.9383 | H42: 5291.2379 | I42: [S4] FY21-22, [S3] FY23-24, [S1] FY25-26
...

Sheet Peers
A1: Peer Comparison - FY26 Audited Standalone (NSE XBRL [S17]); prices 29-May-2026 [S15]; INR crore unless stated
A2: Book value = share capital + reserves & surplus (incl. ESOP o/s where tagged); not tangible BV. ROE = FY26 PAT / avg (Mar-25, Mar-26) equity. NII/assets = (interest earned - expended) / avg total assets.
T3: Raw XBRL values (INR crore = rupees / 1e7; ratios as filed) [S17]
A4: Bank | B4: Symbol | C4: Group | D4: Price (INR) | E4: Shares (cr) | F4: Mkt cap | G4: Book value | H4: FY26 PAT | I4: P/B | J4: P/E | K4: ROE | L4: ROA (rep.) | M4: NII/avg assets | N4: GNPA % | O4: NNPA % | P4: CET1 % | Q4: Adv growth | R4: Dep growth | S4: In regr. | T4: PaidUp (Rs) | U4: Face value | V4: Capital Mar26 | W4: Reserves Mar26 | X4: Capital Mar25 | Y4: Reserves Mar25 | Z4: PAT FY26 | AA4: Int earned | AB4: Int expended | AC4: Assets Mar26 | AD4: Assets Mar25 | AE4: Adv Mar26 | AF4: Adv Mar25 | AG4: Dep Mar26 | AH4: Dep Mar25 | AI4: GNPA% | AJ4: NNPA% | AK4: CET1 | AL4: ROA | AN4: Regr ROE | AO4: Regr P/B | AP4: P/E if num
A5: AU Small Finance Bank | B5: AUBANK | C5: Subject | D5: 984.7 | E5: =T5/U5 -> 74.827 | F5: =D5*E5 -> 73682.147 | G5: =V5+W5 -> 19973.52 | H5: =Z5 -> 2641.25 | I5: =F5/G5 -> 3.6889916 | J5: =IF(H5>0,F5/H5,"n.m.") -> 27.896695 | K5: =H5/((V5+W5+X5+Y5)/2) -> 0.14223286 | L5: =AL5 -> 0.0157 | M5: =(AA5-AB5)/((AC5+AD5)/2) -> 0.052125604 | N5: =AI5 -> 0.0203 | O5: =AJ5 -> 0.0074 | P5: =AK5 -> 0.1686 | Q5: =AE5/AF5-1 -> 0.25382875 | R5: =AG5/AH5-1 -> 0.22847794 | T5: 748.27 | U5: 10 | V5: 748.27 | W5: 19225.25 | X5: 744.53 | Y5: 16421.75 | Z5: 2641.25 | AA5: 18636.34 | AB5: 9523.66 | AC5: 191797.47 | AD5: 157845.67 | AE5: 134275.63 | AF5: 107092.48 | AG5: 152661.16 | AH5: 124268.54 | AI5: 0.0203 | AJ5: 0.0074 | AK5: 0.1686 | AL5: 0.0157 | AP5: =IF(ISNUMBER(J5),J5,"") -> 27.896695
A6: Equitas SFB | B6: EQUITASBNK | C6: SFB | D6: 70.21 | E6: =T6/U6 -> 114.104 | F6: =D6*E6 -> 8011.2418 | G6: =V6+W6 -> 6124.83 | H6: =Z6 -> 103.08 | I6: =F6/G6 -> 1.3079942 | J6: =IF(H6>0,F6/H6,"n.m.") -> 77.718683 | K6: =H6/((V6+W6+X6+Y6)/2) -> 0.016902032 | L6: =AL6 -> 0.0018 | M6: =(AA6-AB6)/((AC6+AD6)/2) -> 0.059784749 | N6: =AI6 -> 0.026 | O6: =AJ6 -> 0.0072 | P6: =AK6 -> 0.1668 | Q6: =AE6/AF6-1 -> 0.18068491 | R6: =AG6/AH6-1 -> 0.079485751 | S6: =IF(K6>0.05,1,0) -> 0 | T6: 1141.04 | U6: 10 | V6: 1141.04 | W6: 4983.79 | X6: 1139.86 | Y6: 4932.66 | Z6: 103.08 | AA6: 6794.24 | AB6: 3403.07 | AC6: 60610.36 | AD6: 52835.63 | AE6: 42751.29 | AF6: 36208.89 | AG6: 46533.09 | AH6: 43106.72 | AI6: 0.026 | AJ6: 0.0072 | AK6: 0.1668 | AL6: 0.0018 | AN6: =IF(S6=1,K6,"") | AO6: =IF(S6=1,I6,"") | AP6: =IF(ISNUMBER(J6),J6,"") -> 77.718683
A7: Ujjivan SFB | B7: UJJIVANSFB | C7: SFB | D7: 54.39 | E7: =T7/U7 -> 194.271 | F7: =D7*E7 -> 10566.4 | G7: =V7+W7 -> 6815.68 | H7: =Z7 -> 692.63 | I7: =F7/G7 -> 1.5503075 | J7: =IF(H7>0,F7/H7,"n.m.") -> 15.255475 | K7: =H7/((V7+W7+X7+Y7)/2) -> 0.10739216 | L7: =AL7 -> 0.0137 | M7: =(AA7-AB7)/((AC7+AD7)/2) -> 0.073571924 | N7: =AI7 -> 0.0226 | O7: =AJ7 -> 0.0043 | P7: =AK7 -> 0.197 | Q7: =AE7/AF7-1 -> 0.26666295 | R7: =AG7/AH7-1 -> 0.21359945 | S7: =IF(K7>0.05,1,0) -> 1 | T7: 1942.71 | U7: 10 | V7: 1942.71 | W7: 4872.97 | X7: 1935 | Y7: 4148.4 | Z7: 692.63 | AA7: 6931.45 | AB7: 3060.45 | AC7: 57541.21 | AD7: 47689.15 | AE7: 39760.55 | AF7: 31390 | AG7: 45668.33 | AH7: 37630.48 | AI7: 0.0226 | AJ7: 0.0043 | AK7: 0.197 | AL7: 0.0137 | AN7: =IF(S7=1,K7,"") -> 0.10739216 | AO7: =IF(S7=1,I7,"") -> 1.5503075 | AP7: =IF(ISNUMBER(J7),J7,"") -> 15.255475
A8: Jana SFB | B8: JSFB | C8: SFB | D8: 495.25 | E8: =T8/U8 -> 10.532 | F8: =D8*E8 -> 5215.973 | G8: =V8+W8 -> 4470.2 | H8: =Z8 -> 326.43 | I8: =F8/G8 -> 1.1668321 | J8: =IF(H8>0,F8/H8,"n.m.") -> 15.978841 | K8: =H8/((V8+W8+X8+Y8)/2) -> 0.07601516 | L8: =AL8 -> 0.0126 | M8: =(AA8-AB8)/((AC8+AD8)/2) -> 0.060367577 | N8: =AI8 -> 0.0246 | O8: =AJ8 -> 0.0092 | P8: =AK8 -> 0.1751 | Q8: =AE8/AF8-1 -> 0.245704 | R8: =AG8/AH8-1 -> 0.22887226 | S8: =IF(K8>0.05,1,0) -> 1 | T8: 105.32 | U8: 10 | V8: 105.32 | W8: 4364.88 | X8: 105.06 | Y8: 4013.29 | Z8: 326.43 | AA8: 5352.87 | AB8: 2759.74 | AC8: 47447.73 | AD8: 38463.62 | AE8: 33827.69 | AF8: 27155.48 | AG8: 35784.49 | AH8: 29119.78 | AI8: 0.0246 | AJ8: 0.0092 | AK8: 0.1751 | AL8: 0.0126 | AN8: =IF(S8=1,K8,"") -> 0.07601516 | AO8: =IF(S8=1,I8,"") -> 1.1668321 | AP8: =IF(ISNUMBER(J8),J8,"") -> 15.978841
A9: Capital SFB | B9: CAPITALSFB | C9: SFB | D9: 274.65 | E9: =T9/U9 -> 4.542 | F9: =D9*E9 -> 1247.4603 | G9: =V9+W9 -> 1461.03 | H9: =Z9 -> 141.39 | I9: =F9/G9 -> 0.85382251 | J9: =IF(H9>0,F9/H9,"n.m.") -> 8.8228326 | K9: =H9/((V9+W9+X9+Y9)/2) -> 0.10095067 | L9: =AL9 -> 0.0123 | M9: =(AA9-AB9)/((AC9+AD9)/2) -> 0.041473252 | N9: =AI9 -> 0.0254 | O9: =AJ9 -> 0.0124 | P9: =AK9 -> 0.1958 | Q9: =AE9/AF9-1 -> 0.20901812 | R9: =AG9/AH9-1 -> 0.20366832 | S9: =IF(K9>0.05,1,0) -> 1 | T9: 45.42 | U9: 10 | V9: 45.42 | W9: 1415.61 | X9: 45.25 | Y9: 1294.89 | Z9: 141.39 | AA9: 1048.6 | AB9: 587.18 | AC9: 12143.94 | AD9: 10107.51 | AE9: 8572.41 | AF9: 7090.39 | AG9: 10017.65 | AH9: 8322.6 | AI9: 0.0254 | AJ9: 0.0124 | AK9: 0.1958 | AL9: 0.0123 | AN9: =IF(S9=1,K9,"") -> 0.10095067 | AO9: =IF(S9=1,I9,"") -> 0.85382251 | AP9: =IF(ISNUMBER(J9),J9,"") -> 8.8228326
A10: Suryoday SFB | B10: SURYODAY | C10: SFB | D10: 163.59 | E10: =T10/U10 -> 10.629 | F10: =D10*E10 -> 1738.7981 | G10: =V10+W10 -> 2078.32 | H10: =Z10 -> 151.97 | I10: =F10/G10 -> 0.83663637 | J10: =IF(H10>0,F10/H10,"n.m.") -> 11.441719 | K10: =H10/((V10+W10+X10+Y10)/2) -> 0.075882369 | L10: =AL10 -> 0.0089 | M10: =(AA10-AB10)/((AC10+AD10)/2) -> 0.061902032 | N10: =AI10 -> 0.0655 | O10: =AJ10 -> 0.0421 | P10: =AK10 -> 0.1959 | Q10: =AE10/AF10-1 -> 0.2911879 | R10: =AG10/AH10-1 -> 0.32273685 | S10: =IF(K10>0.05,1,0) -> 1 | T10: 106.29 | U10: 10 | V10: 106.29 | W10: 1972.03 | X10: 106.28 | Y10: 1820.81 | Z10: 151.97 | AA10: 2160.29 | AB10: 1061.58 | AC10: 19883.96 | AD10: 15614.39 | AE10: 12878.76 | AF10: 9974.35 | AG10: 13994.04 | AH10: 10579.61 | AI10: 0.0655 | AJ10: 0.0421 | AK10: 0.1959 | AL10: 0.0089 | AN10: =IF(S10=1,K10,"") -> 0.075882369 | AO10: =IF(S10=1,I10,"") -> 0.83663637 | AP10: =IF(ISNUMBER(J10),J10,"") -> 11.441719
A11: ESAF SFB | B11: ESAFSFB | C11: SFB | D11: 28.61 | E11: =T11/U11 -> 51.566 | F11: =D11*E11 -> 1475.3033 | G11: =V11+W11 -> 1780.04 | H11: =Z11 -> -166.4 | I11: =F11/G11 -> 0.82880343 | J11: =IF(H11>0,F11/H11,"n.m.") -> n.m. | K11: =H11/((V11+W11+X11+Y11)/2) -> -0.089341083 | L11: =AL11 -> -0.006 | M11: =(AA11-AB11)/((AC11+AD11)/2) -> 0.086509951 | N11: =AI11 -> 0.0541 | O11: =AJ11 -> 0.0177 | P11: =AK11 -> 0.1423 | Q11: =AE11/AF11-1 -> 0.19782426 | R11: =AG11/AH11-1 -> 0.11057189 | S11: =IF(K11>0.05,1,0) -> 0 | T11: 515.66 | U11: 10 | V11: 515.66 | W11: 1264.38 | X11: 515.43 | Y11: 1429.58 | Z11: -166.4 | AA11: 4348.23 | AB11: 1837.44 | AC11: 30867.98 | AD11: 27178.29 | AE11: 21594.22 | AF11: 18027.87 | AG11: 25850.16 | AH11: 23276.44 | AI11: 0.0541 | AJ11: 0.0177 | AK11: 0.1423 | AL11: -0.006 | AN11: =IF(S11=1,K11,"") | AO11: =IF(S11=1,I11,"") | AP11: =IF(ISNUMBER(J11),J11,"")
A12: Utkarsh SFB | B12: UTKARSHBNK | C12: SFB | D12: 13.26 | E12: =T12/U12 -> 177.952 | F12: =D12*E12 -> 2359.6435 | G12: =V12+W12 -> 2775.6 | H12: =Z12 -> -1150.98 | I12: =F12/G12 -> 0.85013818 | J12: =IF(H12>0,F12/H12,"n.m.") -> n.m. | K12: =H12/((V12+W12+X12+Y12)/2) -> -0.40033391 | L12: =AL12 -> -0.0416 | M12: =(AA12-AB12)/((AC12+AD12)/2) -> 0.051818611 | N12: =AI12 -> 0.0771 | O12: =AJ12 -> 0.0329 | P12: =AK12 -> 0.1498 | Q12: =AE12/AF12-1 -> -0.034562589 | R12: =AG12/AH12-1 -> 0.0040935374 | S12: =IF(K12>0.05,1,0) -> 0 | T12: 1779.52 | U12: 10 | V12: 1779.52 | W12: 996.08 | X12: 1101.61 | Y12: 1872.89 | Z12: -1150.98 | AA12: 3378.78 | AB12: 1902.04 | AC12: 28869.07 | AD12: 28127.44 | AE12: 18069.59 | AF12: 18716.48 | AG12: 21653.98 | AH12: 21565.7 | AI12: 0.0771 | AJ12: 0.0329 | AK12: 0.1498 | AL12: -0.0416 | AN12: =IF(S12=1,K12,"") | AO12: =IF(S12=1,I12,"") | AP12: =IF(ISNUMBER(J12),J12,"")
A13: IDFC FIRST Bank | B13: IDFCFIRSTB | C13: Private | D13: 71.32 | E13: =T13/U13 -> 860.17 | F13: =D13*E13 -> 61347.324 | G13: =V13+W13 -> 47351.84 | H13: =Z13 -> 1636.36 | I13: =F13/G13 -> 1.2955637 | J13: =IF(H13>0,F13/H13,"n.m.") -> 37.490115 | K13: =H13/((V13+W13+X13+Y13)/2) -> 0.038308863 | L13: =AL13 -> 0.0044 | M13: =(AA13-AB13)/((AC13+AD13)/2) -> 0.05706107 | N13: =AI13 -> 0.0161 | O13: =AJ13 -> 0.0048 | P13: =AK13 -> 0.1373 | Q13: =AE13/AF13-1 -> 0.20281222 | R13: =AG13/AH13-1 -> 0.16824731 | S13: =IF(K13>0.05,1,0) -> 0 | T13: 8601.7 | U13: 10 | V13: 8889.57 | W13: 38462.27 | X13: 7322.11 | Y13: 30755.89 | Z13: 1636.36 | AA13: 40548.82 | AB13: 19333.55 | AC13: 399780.09 | AD13: 343818.65 | AE13: 280390.6 | AF13: 233112.53 | AG13: 294474.55 | AH13: 252065.25 | AI13: 0.0161 | AJ13: 0.0048 | AK13: 0.1373 | AL13: 0.0044 | AN13: =IF(S13=1,K13,"") | AO13: =IF(S13=1,I13,"") | AP13: =IF(ISNUMBER(J13),J13,"") -> 37.490115
A14: Bandhan Bank | B14: BANDHANBNK | C14: Private | D14: 208.3 | E14: =T14/U14 -> 161.097 | F14: =D14*E14 -> 33556.505 | G14: =V14+W14 -> 25574.89 | H14: =Z14 -> 1223.56 | I14: =F14/G14 -> 1.312088 | J14: =IF(H14>0,F14/H14,"n.m.") -> 27.425304 | K14: =H14/((V14+W14+X14+Y14)/2) -> 0.048766937 | L14: =AL14 -> 0.0064 | M14: =(AA14-AB14)/((AC14+AD14)/2) -> 0.053798755 | N14: =AI14 -> 0.0327 | O14: =AJ14 -> 0.0097 | P14: =AK14 -> 0.1804 | Q14: =AE14/AF14-1 -> 0.13725909 | R14: =AG14/AH14-1 -> 0.10007076 | S14: =IF(K14>0.05,1,0) -> 0 | T14: 1610.97 | U14: 10 | V14: 1610.97 | W14: 23963.92 | X14: 1610.97 | Y14: 22994.04 | Z14: 1223.56 | AA14: 21689.11 | AB14: 10859.42 | AC14: 211123.73 | AD14: 191476.29 | AE14: 150103.78 | AF14: 131987.32 | AG14: 166344.45 | AH14: 151212.5 | AI14: 0.0327 | AJ14: 0.0097 | AK14: 0.1804 | AL14: 0.0064 | AN14: =IF(S14=1,K14,"") | AO14: =IF(S14=1,I14,"") | AP14: =IF(ISNUMBER(J14),J14,"") -> 27.425304
A15: RBL Bank | B15: RBLBANK | C15: Private | D15: 345 | E15: =T15/U15 -> 61.811 | F15: =D15*E15 -> 21324.795 | G15: =V15+W15 -> 16604.9 | H15: =Z15 -> 822.44 | I15: =F15/G15 -> 1.2842471 | J15: =IF(H15>0,F15/H15,"n.m.") -> 25.928694 | K15: =H15/((V15+W15+X15+Y15)/2) -> 0.051064691 | L15: =AL15 -> 0.0053 | M15: =(AA15-AB15)/((AC15+AD15)/2) -> 0.038847527 | N15: =AI15 -> 0.0145 | O15: =AJ15 -> 0.0039 | P15: =AK15 -> 0.1277 | Q15: =AE15/AF15-1 -> 0.23336292 | R15: =AG15/AH15-1 -> 0.2530481 | S15: =IF(K15>0.05,1,0) -> 1 | T15: 618.11 | U15: 10 | V15: 618.11 | W15: 15986.79 | X15: 607.88 | Y15: 14998.91 | Z15: 822.44 | AA15: 14335.55 | AB15: 7976.01 | AC15: 180684.81 | AD15: 146725.48 | AE15: 114231.94 | AF15: 92618.27 | AG15: 139017.58 | AH15: 110943.53 | AI15: 0.0145 | AJ15: 0.0039 | AK15: 0.1277 | AL15: 0.0053 | AN15: =IF(S15=1,K15,"") -> 0.051064691 | AO15: =IF(S15=1,I15,"") -> 1.2842471 | AP15: =IF(ISNUMBER(J15),J15,"") -> 25.928694
A16: Federal Bank | B16: FEDERALBNK | C16: Private | D16: 288.95 | E16: =T16/U16 -> 246.43 | F16: =D16*E16 -> 71205.948 | G16: =V16+W16 -> 38705.07 | H16: =Z16 -> 4117.32 | I16: =F16/G16 -> 1.839706 | J16: =IF(H16>0,F16/H16,"n.m.") -> 17.294247 | K16: =H16/((V16+W16+X16+Y16)/2) -> 0.11417069 | L16: =AL16 -> 0.0115 | M16: =(AA16-AB16)/((AC16+AD16)/2) -> 0.028939659 | N16: =AI16 -> 0.0162 | O16: =AJ16 -> 0.002 | P16: =AK16 -> 0.1593 | Q16: =AE16/AF16-1 -> 0.12671792 | R16: =AG16/AH16-1 -> 0.10668849 | S16: =IF(K16>0.05,1,0) -> 1 | T16: 492.86 | U16: 2 | V16: 492.86 | W16: 38212.21 | X16: 491.17 | Y16: 32929.45 | Z16: 4117.32 | AA16: 27695.38 | AB16: 17037.97 | AC16: 387521.49 | AD16: 349004.8 | AE16: 264594.37 | AF16: 234836.39 | AG16: 313909.39 | AH16: 283647.47 | AI16: 0.0162 | AJ16: 0.002 | AK16: 0.1593 | AL16: 0.0115 | AN16: =IF(S16=1,K16,"") -> 0.11417069 | AO16: =IF(S16=1,I16,"") -> 1.839706 | AP16: =IF(ISNUMBER(J16),J16,"") -> 17.294247
A17: City Union Bank | B17: CUB | C17: Private | D17: 255.45 | E17: =T17/U17 -> 74.3 | F17: =D17*E17 -> 18979.935 | G17: =V17+W17 -> 10564.86 | H17: =Z17 -> 1326.23 | I17: =F17/G17 -> 1.7965155 | J17: =IF(H17>0,F17/H17,"n.m.") -> 14.311194 | K17: =H17/((V17+W17+X17+Y17)/2) -> 0.13241458 | L17: =AL17 -> 0.0156 | M17: =(AA17-AB17)/((AC17+AD17)/2) -> 0.032406284 | N17: =AI17 -> 0.0191 | O17: =AJ17 -> 0.0068 | P17: =AK17 -> 0.2082 | Q17: =AE17/AF17-1 -> 0.26485386 | R17: =AG17/AH17-1 -> 0.23269231 | S17: =IF(K17>0.05,1,0) -> 1 | T17: 74.3 | U17: 1 | V17: 74.3 | W17: 10490.56 | X17: 74.1 | Y17: 9392.52 | Z17: 1326.23 | AA17: 6869.76 | AB17: 4039.92 | AC17: 97024.4 | AD17: 77623.21 | AE17: 65875.17 | AF17: 52081.25 | AG17: 78307.95 | AH17: 63525.95 | AI17: 0.0191 | AJ17: 0.0068 | AK17: 0.2082 | AL17: 0.0156 | AN17: =IF(S17=1,K17,"") -> 0.13241458 | AO17: =IF(S17=1,I17,"") -> 1.7965155 | AP17: =IF(ISNUMBER(J17),J17,"") -> 14.311194
A19: Group statistics
A20: SFB median (7 peers) | I20: =MEDIAN(I6:I12) -> 0.85382251 | J20: =MEDIAN(AP6:AP12) -> 15.255475 | K20: =MEDIAN(K6:K12) -> 0.075882369 | L20: =MEDIAN(L6:L12) -> 0.0089 | M20: =MEDIAN(M6:M12) -> 0.060367577 | N20: =MEDIAN(N6:N12) -> 0.026 | O20: =MEDIAN(O6:O12) -> 0.0124 | P20: =MEDIAN(P6:P12) -> 0.1751 | Q20: =MEDIAN(Q6:Q12) -> 0.20901812 | R20: =MEDIAN(R6:R12) -> 0.20366832
A21: Private median (5 peers) | I21: =MEDIAN(I13:I17) -> 1.312088 | J21: =MEDIAN(AP13:AP17) -> 25.928694 | K21: =MEDIAN(K13:K17) -> 0.051064691 | L21: =MEDIAN(L13:L17) -> 0.0064 | M21: =MEDIAN(M13:M17) -> 0.038847527 | N21: =MEDIAN(N13:N17) -> 0.0162 | O21: =MEDIAN(O13:O17) -> 0.0048 | P21: =MEDIAN(P13:P17) -> 0.1593 | Q21: =MEDIAN(Q13:Q17) -> 0.20281222 | R21: =MEDIAN(R13:R17) -> 0.16824731
A22: All-peer median (12) | I22: =MEDIAN(I6:I17) -> 1.2899054 | J22: =MEDIAN(AP6:AP17) -> 16.636544 | K22: =MEDIAN(K6:K17) -> 0.06347353 | L22: =MEDIAN(L6:L17) -> 0.00765 | M22: =MEDIAN(M6:M17) -> 0.055429913 | N22: =MEDIAN(N6:N17) -> 0.025 | O22: =MEDIAN(O6:O17) -> 0.0082 | P22: =MEDIAN(P6:P17) -> 0.17095 | Q22: =MEDIAN(Q6:Q17) -> 0.20591517 | R22: =MEDIAN(R6:R17) -> 0.18595782
A23: P/E medians ignore loss-makers (n.m.).
A25: P/B vs ROE cross-section (profitable peers with ROE > 5%)
A26: Peer rows used (1 = include) | C26: =SUM(S6:S17) -> 7
A27: Slope (P/B per 1.00 of ROE) | C27: =SLOPE(AO6:AO17,AN6:AN17) -> 9.0504888
A28: Intercept | C28: =INTERCEPT(AO6:AO17,AN6:AN17) -> 0.48197687
A29: R-squared | C29: =RSQ(AO6:AO17,AN6:AN17) -> 0.3681024
A30: Peer-implied P/B at AU FY26 ROE | C30: =C28+C27*K5 -> 1.7692538
A31: AU actual P/B | C31: =I5 -> 3.6889916
A32: Caution: small sample, single year, ROE depressed by one-offs for several peers; regression is descriptive only.

Sheet Beta
A1: Beta: AUBANK vs NIFTY 50, weekly closes 31-May-2024 to 29-May-2026 [S15][S16]
A3: Week end | B3: AUBANK close | C3: NIFTY 50 | D3: AU log ret | E3: NIFTY log ret | F3: Result
A4: 2024-05-31 | B4: 653.1 | C4: 22530.7 | F4: =SLOPE(D5:D108,E5:E108) -> 1.0232624
A5: 2024-06-07 | B5: 669 | C5: 23290.15 | D5: =LN(B5/B4) -> 0.024053803 | E5: =LN(C5/C4) -> 0.033151701 | F5: =CORREL(D5:D108,E5:E108) -> 0.45613513
A6: 2024-06-14 | B6: 661.25 | C6: 23465.6 | D6: =LN(B6/B5) -> -0.011652077 | E6: =LN(C6/C5) -> 0.0075049945 | F6: =0.67*F4+0.33 -> 1.0155858
A7: 2024-06-21 | B7: 667.6 | C7: 23501.1 | D7: =LN(B7/B6) -> 0.0095572086 | E7: =LN(C7/C6) -> 0.0015117096 | F7: F4 = raw OLS beta (used); F5 = correlation; F6 = Blume-adjusted (reference). Week-end = last trading day of each week.
A8: 2024-06-28 | B8: 672.05 | C8: 24010.6 | D8: =LN(B8/B7) -> 0.0066435507 | E8: =LN(C8/C7) -> 0.021448171
A9: 2024-07-05 | B9: 672.6 | C9: 24323.85 | D9: =LN(B9/B8) -> 0.00081805679 | E9: =LN(C9/C8) -> 0.012961951
A10: 2024-07-12 | B10: 643.8 | C10: 24502.15 | D10: =LN(B10/B9) -> -0.04376268 | E10: =LN(C10/C9) -> 0.0073035183
A11: 2024-07-19 | B11: 633.65 | C11: 24530.9 | D11: =LN(B11/B10) -> -0.015891367 | E11: =LN(C11/C10) -> 0.0011726786
A12: 2024-07-26 | B12: 650.4 | C12: 24834.85 | D12: =LN(B12/B11) -> 0.026090807 | E12: =LN(C12/C11) -> 0.012314361
A13: 2024-08-02 | B13: 637.6 | C13: 24717.7 | D13: =LN(B13/B12) -> -0.019876431 | E13: =LN(C13/C12) -> -0.0047283225
A14: 2024-08-09 | B14: 625.95 | C14: 24367.5 | D14: =LN(B14/B13) -> -0.018440632 | E14: =LN(C14/C13) -> -0.014269309
A15: 2024-08-16 | B15: 613.2 | C15: 24541.15 | D15: =LN(B15/B14) -> -0.020579349 | E15: =LN(C15/C14) -> 0.0071010232
A16: 2024-08-23 | B16: 625.8 | C16: 24823.15 | D16: =LN(B16/B15) -> 0.020339684 | E16: =LN(C16/C15) -> 0.011425385
A17: 2024-08-30 | B17: 688.7 | C17: 25235.9 | D17: =LN(B17/B16) -> 0.095774931 | E17: =LN(C17/C16) -> 0.016490898
A18: 2024-09-06 | B18: 703 | C18: 24852.15 | D18: =LN(B18/B17) -> 0.020551129 | E18: =LN(C18/C17) -> -0.015323316
A19: 2024-09-13 | B19: 722.9 | C19: 25356.5 | D19: =LN(B19/B18) -> 0.027914008 | E19: =LN(C19/C18) -> 0.02009084
... A108: 2026-05-29 | B108: 984.7 | C108: 23547.75 | D108: =LN(B108/B107) -> 0.0069296109 | E108: =LN(C108/C107) -> -0.0072587882

Sheet Checks
A1: Model Integrity Checks
A2: Overall Status | B2: =IF(COUNTIF(C4:C23,"FAIL")=0,"ALL CHECKS PASS","CHECK FAILURES: "&COUNTIF(C4:C23,"FAIL")) -> ALL CHECKS PASS
A4: Hist: interest earned sub-items sum to reported (all years, abs diff Rs cr) | B4: =SUMPRODUCT(ABS(Hist!C10:H10-Hist!C25:H25)) -> 0 | C4: =IF(B4<=0.01,"PASS","FAIL") -> PASS
A5: Hist: PBT rebuilt from components equals reported PBT | B5: =SUMPRODUCT(ABS(Hist!C21:H21-Hist!C26:H26)) -> 3.8653525e-12 | C5: =IF(B5<=0.01,"PASS","FAIL") -> PASS
A6: Hist: PAT rebuilt equals reported PAT | B6: =SUMPRODUCT(ABS(Hist!C23:H23-Hist!C24:H24)) -> 0.0001 | C6: =IF(B6<=0.01,"PASS","FAIL") -> PASS
A7: Hist: total assets = total liabilities & equity (sum of abs diffs) | B7: =SUMPRODUCT(ABS(Hist!C35:H35-Hist!C43:H43)) -> 1.4551915e-11 | C7: =IF(B7<=0.01,"PASS","FAIL") -> PASS
A8: Hist: total liabilities & equity equals reported total | B8: =SUMPRODUCT(ABS(Hist!C43:H43-Hist!C44:H44)) -> 1.4551915e-11 | C8: =IF(B8<=0.01,"PASS","FAIL") -> PASS
A9: Hist: CRAR from Pillar 3 capital/RWA equals reported CRAR (max abs diff, FY22-26) | B9: =MAX(ABS(Hist!D58-Hist!D60),ABS(Hist!E58-Hist!E60),ABS(Hist!F58-Hist!F60),ABS(Hist!G58-Hist!G60),ABS(Hist!H58-Hist!H60)) -> 3.7571466e-05 | C9: =IF(B9<=0.01,"PASS","FAIL") -> PASS
A10: Model: FY26A segment GLP sums to reported GLP 140,327 | B10: =ABS(Model!E18-140327) -> 0 | C10: =IF(B10<=0.01,"PASS","FAIL") -> PASS
A11: Model: FY26A PAT equals Hist PAT | B11: =ABS(Model!E70-Hist!H23) -> 0 | C11: =IF(B11<=0.01,"PASS","FAIL") -> PASS
A12: Model: balance sheet balances every year (sum of abs diffs) | B12: =SUMPRODUCT(ABS(Model!C44:J44)) -> 0 | C12: =IF(B12<=0.01,"PASS","FAIL") -> PASS
A13: Model: equity roll-forward closing = capital + reserves (forecast) | B13: =SUMPRODUCT(ABS(Model!F80:J80-Model!F81:J81-Model!F82:J82)) -> 0 | C13: =IF(B13<=0.01,"PASS","FAIL") -> PASS
A14: Model: retained-earnings movement = PAT - dividends paid (forecast) | B14: =SUMPRODUCT(ABS((Model!F82:J82-Model!E82:I82)-(Model!F77:J77+Model!F78:J78-(Model!F81:J81-Model!E81:I81))-(Model!F70:J70-Model!F76:J76))) -> 5.9117156e-12 | C14: =IF(B14<=0.01,"PASS","FAIL") -> PASS
A15: Model: share count roll-forward (closing = opening + ESOP + new issue) | B15: =SUMPRODUCT(ABS(Model!F83:J83-Model!E83:I83-Inputs!C159:G159-Inputs!C164:G164/(Inputs!C169:G169*Model!E84:I84))) -> 2.8310687e-14 | C15: =IF(B15<=0.01,"PASS","FAIL") -> PASS
A16: Model: capital ratio consistency - CET1 <= CRAR and Tier 2 <= Tier 1 every year | B16: =SUMPRODUCT((Model!C99:J99>Model!C100:J100)+(Model!C93:J93>Model!C92:J92)) -> 0 | C16: =IF(B16<=0.01,"PASS","FAIL") -> PASS
A17: Model: CRAR >= regulatory minimum every forecast year (count of breaches) | B17: =SUMPRODUCT(--(Model!F104:J104<0)) -> 0 | C17: =IF(B17<=0.01,"PASS","FAIL") -> PASS
A18: Model: CET1 >= internal floor every forecast year (count of breaches) | B18: =SUMPRODUCT(--(Model!F105:J105<0)) -> 0 | C18: =IF(B18<=0.01,"PASS","FAIL") -> PASS
A19: Model: cash & bank >= minimum liquidity every forecast year (count of breaches) | B19: =SUMPRODUCT(--(Model!F47:J47<Inputs!C36)) -> 0 | C19: =IF(B19<=0.01,"PASS","FAIL") -> PASS
A20: Model: CD ratio <= funding cap every forecast year (count of breaches) | B20: =SUMPRODUCT(--(Model!F26:J26>Inputs!C37)) -> 0 | C20: =IF(B20<=0.01,"PASS","FAIL") -> PASS
A21: Valuation: CoE > terminal growth | B21: =IF(Valuation!B5>Valuation!B6,0,1) -> 0 | C21: =IF(B21<=0.01,"PASS","FAIL") -> PASS
A22: Valuation: implied fade payout between 0% and 100% | B22: =SUMPRODUCT((Valuation!H25:Q25<0)+(Valuation!H25:Q25>1)) -> 0 | C22: =IF(B22<=0.01,"PASS","FAIL") -> PASS
A23: Sensitivity grid reproduces value/share | B23: =IFERROR(ABS(INDEX(Valuation!C72:I72,MATCH(Valuation!B7,Valuation!C67:I67,0))-Valuation!B36),0) -> 0 | C23: =IF(B23<=0.01,"PASS","FAIL") -> PASS

Sheet DataDict
A1: Data Dictionary and Definitions
A3: Metric | B3: Model definition (used consistently for history, forecast and peers where stated)
A4: Gross loan portfolio (GLP) | B4: Company-reported gross advances including off-book (securitised/IBPC) and before provisions; segment split per loan-mix slide
A5: Net advances | B5: Balance-sheet advances (net of provisions)
A6: Yield on advances | B6: Interest/discount on advances / simple average of opening and closing net advances
A7: Cost of funds (CoF) | B7: Interest expended / simple average of (deposits + borrowings)
A8: NIM | B8: NII / simple average interest-earning assets (net advances + investments + cash & bank balances)
A9: Other income ratio | B9: Other income / average non-cash assets (net adv + investments + fixed + other assets)
A10: Opex ratio | B10: Operating expenses / average non-cash assets; also shown / avg total assets (company style)
A11: Cost-to-income | B11: Operating expenses / (NII + other income)
A12: Credit cost | B12: Provisions & contingencies (ex tax) / average GLP
A13: GNPA / NNPA ratio | B13: As reported: gross NPA / gross advances; net NPA / net advances
A14: Specific PCR | B14: 1 - NNPA / GNPA (excludes technical write-offs)
... A25: Peer NII / assets | B25: (Interest earned - interest expended) / avg total assets

Sheet Sources
A1: Source log (primary sources only; all published on or before the 29-May-2026 cut-off)
A3: ID | B3: Document | C3: Period | D3: Published | E3: Page / table / tag | F3: URL | G3: Units | H3: Used for
A4: S1 | B4: AU SFB - Audited financial results Q4 & FY26 (Reg 33), standalone | C4: FY26, FY25 | D4: 27-Apr-2026 | E4: Statement of results; Statement of assets & liabilities; notes (dividend, ESOP allotment, CFO, fund-raise enabling) | F4: https://www.au.bank.in/pdfs/quaterly-reports/year-25/financial-result/Q4FY26-Result.pdf | G4: INR lakh | H4: Hist FY25-FY26 P&L/BS, EPS, NPA, CRAR
A5: S2 | B5: NSE Integrated Filing - Financials XBRL, AU SFB, standalone, FY26 audited | C5: FY26 | D5: 27-Apr-2026 | E5: XBRL tags (InterestEarned, ..., CET1Ratio, Deposits, Advances) | F5: https://nsearchives.nseindia.com/corporate/xbrl/INTEGRATED_FILING_BANKING_1659849_27042026112414_WEB.xml | G5: INR (rupees) | H5: Hist FY26 verification; Peers AU row
A6: S3 | B6: AU SFB - Audited financial results Q4 & FY24 (standalone) | C6: FY24, FY23 | D6: 24-Apr-2024 | E6: Statement of results; assets & liabilities; notes (Fincare scheme, exceptional item) | F6: https://www.au.bank.in/pdfs/quaterly-reports/year-23/financial-result/Q4FY24-Financial-Result.pdf | G6: INR lakh | H6: Hist FY23-FY24
A7: S4 | B7: AU SFB - Audited financial results Q4 & FY22 (standalone) | C7: FY22, FY21 (regrouped) | D7: 26-Apr-2022 | E7: Statement of results; assets & liabilities; notes (dividend, 1:1 bonus) | F7: https://www.au.bank.in/pdfs/quaterly-reports/year-21/financial-result/Q4FY22-Financial-Results.pdf | G7: INR lakh | H7: Hist FY21-FY22
A8: S5 | B8: NSE legacy results XBRL, AU SFB, Q4 filings FY21-FY24 (annual context) | C8: FY21-FY24 | D8: 30-Apr-2021; 27-Apr-2022; 26-Apr-2023; 25-Apr-2024 | E8: Context FourD | F8: https://nsearchives.nseindia.com/corporate/xbrl/BANKING_69558_445061_30042021021223_WEB.xml ; ..._83651_648527_27042022042456_WEB.xml ; ..._90859_833207_26042023041609.xml ; ..._104695_1107810_25042024013649.xml | G8: INR (rupees) | H8: Verification of FY21-FY24 P&L
A9: S6 | B9: AU SFB - Basel II Pillar 3 disclosures at 31-Mar-2026 | C9: Mar-26 | D9: not stated on document (year-end disclosure) | E9: Capital funds, RWA, DF-2 ratios; regulatory minima (CET1 6%, Tier-1 7.5%, CRAR 15%) | F9: https://www.au.bank.in/pdfs/regulatory-disclosures/2025-2026/PILLAR-3-Disclosures-at_March-31-2026.pdf | G9: INR crore | H9: Tier 1, Tier 2, RWA FY26; SFB minima
A10: S7 | B10: AU SFB - Basel II Pillar 3 disclosures at 31-Mar-2025 / 2024 / 2023 / 2022 | C10: Mar-22 to Mar-25 | D10: year-end disclosures | E10: Capital funds position; capital requirement table | F10: https://www.au.bank.in/pdfs/regulatory-disclosures/2024-2025/basel-ll-pillar-lll-disclosures-basel-ii-pillar-3-disclosuresat-march-31-2025.pdf (and 2023-24, 2022-23, 2021-22 equivalents on the Regulatory Disclosures page) | G10: INR lakh | H10: Tier 1, Tier 2, RWA FY22-FY25
A11: S8 | B11: AU SFB - Q4FY26 earnings presentation | C11: Q4FY26 / FY26 | D11: 27-Apr-2026 | E11: Loan-mix slide (GLP by segment Mar-26/Dec-25/Mar-25); deposits; NIM/CoF; asset quality | F11: https://www.au.bank.in/pdfs/quaterly-reports/year-25/investors-presentation/Q4FY26-PPT.pdf | G11: INR crore | H11: Segment GLP, company-reported NIM, CoF, CASA
A12: S9 | B12: AU SFB - Q4FY26 results press release | C12: Q4FY26 / FY26 | D12: 27-Apr-2026 | E12: Headline metrics | F12: https://www.au.bank.in/pdfs/press-release/2026/PR-final-27th-Apr.pdf | G12: INR crore | H12: CASA 43,357 cr (28%), GLP 140,327, BVPS 267, ROE 14.2%, credit cost 0.96% of avg assets, LCR 119%, touchpoints 2,790
A13: S10 | B13: AU SFB - Q4FY26 earnings call transcript | C13: Q4FY26 | D13: Call Date 27-Apr-2026 | E13: Management commentary | F13: https://www.au.bank.in/pdfs/quaterly-reports/year-25/call-transcript/AUSFB-Q4FY26-Transcript.pdf | G13: n/a | H13: Guidance: growth 2-2.5x nominal GDP; ROA ~1.8% aspiration FY27; credit cost ~90bp (of assets); opex/assets <4% FY27
A14: S11 | B14: AU SFB - Q4FY24 investor presentation | C14: Q4FY24 / FY24 | D14: 24-Apr-2024 | E14: CASA, NIM, CoF, loan mix Mar-24 | F14: https://www.au.bank.in/pdfs/quaterly-reports/year-23/investors-presentation/Q4FY24-investor-ppt-vf.pdf | G14: INR crore | H14: CASA FY23-FY24, company NIM/CoF FY23-FY24, GLP Mar-24
... A23: S20 | B23: RBI Weekly Statistical Supplement extract (press release, 29-May-2026), Table 4: Scheduled Commercial Banks - Business in India | C23: as on 15-May-2026 | D23: 29-May-2026 | E23: Aggregate deposits YoY +12.2%; bank credit YoY +16.2% | F23: https://www.rbi.org.in/Scripts/BS_PressReleaseDisplay.aspx?prid=62826 | G23: INR crore / % | H23: System growth context for funding-supportability test
